## Исключения
Исключения в Python — это специальные объекты, которые создаются в случае возникновения ошибки во время выполнения программы. Они используются для обработки ошибок и исключительных ситуаций в Python.

Исключения могут возникать во время выполнения программы из-за ошибок в коде, неправильных данных, недоступности файлов, отсутствия необходимых библиотек и т.д. Если исключение не обработано, то оно приводит к остановке программы и выводу сообщения об ошибке.

Для обработки исключений в Python используется конструкция try-except. Код, который может вызвать исключение, заключается в блок try, а обработка исключения осуществляется в блоке except. Если в блоке try произошло исключение, то программа переходит к блоку except, который содержит код для обработки этого исключения.

Пример использования конструкции try-except для обработки исключения:

```
try:
    # код, который может вызвать исключение
    x = 10 / 0
except ZeroDivisionError:
    # код для обработки исключения
    print("Деление на ноль!")
```

В данном примере мы пытаемся разделить число 10 на 0, что вызывает исключение ZeroDivisionError. В блоке except мы обрабатываем это исключение и выводим сообщение "Деление на ноль!".

Кроме блока except, в конструкции try-except может быть использован блок else, который содержит код, который будет выполнен в случае отсутствия исключений. Также может быть использован блок finally, который содержит код, который будет выполнен в любом случае, даже если произошло исключение.

Пример использования блоков else и finally в конструкции try-except:

```
try:
    # код, который может вызвать исключение
    x = int(input("Введите число: "))
except ValueError:
    # код для обработки исключения
    print("Вы ввели неправильное значение!")
else:
    # код, который будет выполнен, если исключение не произошло
    print("Вы ввели число:", x)
finally:
    # код, который будет выполнен в любом случае
    print("Конец программы")
```

В данном примере мы запрашиваем у пользователя ввод числа с помощью функции input и пытаемся преобразовать его в целое число с помощью функции int. Если введено неправильное значение, то происходит исключение ValueError, которое мы обрабатываем в блоке except. Если введено правильное значение, то мы выводим его на экран в блоке else. В блоке finally мы выводим сообщение "Конец программы".

Кроме конструкции try-ex, в Python есть встроенные исключения, которые могут быть использованы для обработки определенных ошибок. Например:

- TypeError - возникает при неправильном использовании типов данных
- NameError - возникает при попытке использования несуществующей переменной или функции
- IndexError - возникает при попытке обращения к элементу списка или кортежа, который находится за его границами
- KeyError - возникает при попытке обращения к несуществующему ключу словаря
- IOError - возникает при недоступности файлов или ошибках ввода-вывода

Для создания собственных исключений в Python можно создать новый класс, который будет наследоваться от базового класса Exception. В таком классе можно определить свойства и методы, которые будут использоваться при обработке исключения.

Пример создания собственного исключения в Python:

```
class MyError(Exception):
    def __init__(self, message):
        self.message = message
    def __str__(self):
        return self.message

try:
    x = int(input("Введите число: "))
    if x < 0:
        raise MyError("Число должно быть положительным!")
except ValueError:
    print("Вы ввели неправильное значение!")
except MyError as error:
    print(error)
```

В данном примере мы создаем класс MyError, который наследуется от базового класса Exception. В конструкторе класса мы определяем свойство message, которое будет использоваться для хранения сообщения об ошибке. В методе __str__ мы определяем, как будет выводиться это сообщение на экран.

Далее мы запрашиваем у пользователя ввод числа и проверяем, что оно положительное. Если число отрицательное, то мы вызываем наше собственное исключение MyError с сообщением "Число должно быть положительным!". Если пользователь ввел неправильное значение, то возникает исключение ValueError, которое мы обрабатываем в блоке except. Если число отрицательное, то мы обрабатываем наше собственное исключение MyError и выводим сообщение об ошибке на экран.

Важно правильно обрабатывать исключения в Python, чтобы предотвратить возможные ошибки в работе программы и обеспечить ее стабильность и безопасность.


